Workbook

Sheet 총괄표
B1: SLM 스마트 물관리 시스템 — 개발대가 산정 총괄표
B2: 산정 기준: SW사업 대가산정 가이드(KOSA) 단일 FP유형(간이법) + 엔지니어링(SW기술자 평균임금 2025)
B3: 기능 기준일: 2026-10-15 (메뉴 57종 · AI 채팅 인텐트 81종 · Migration 0143)
B5: 구분 | C5: 산정 방법 | D5: 금액(원) | E5: 비고
B6: ① 소프트웨어 개발비 | C6: 기능점수(FP) × 단가 × 보정계수 + 이윤 | D6: ='SW개발비 산정'!I11 | E6: FP산정(간이법)·SW개발비 산정 시트
B7: ② 구축·설치 엔지니어링 | C7: M/M × SW기술자 평균임금 + 제경비 + 기술료 | D7: ='엔지니어링 내역'!H25 | E7: 엔지니어링 내역 시트
B8: 합계 (부가세 별도) | D8: =SUM(D6:D7)
B10: ※ 기능점수당 단가는 KOSA 2024 가이드(605,784원) 기준 — 최신 공표 단가 확인 후 'SW개발비 산정'!C7 갱신
B11: ※ 하드웨어·상용SW 구입비, 유지관리(운영)비는 본 산정 범위 외

Sheet FP산정(간이법)
B1: 기능점수 산정 (간이법 평균복잡도 적용)
B3: 기능명 | E3: 데이터 및 트랜잭션 기능 | F3: FP 산출 | G3: 사용자관점 기능 | H3: 비고
B4: ①어플리케이션명 | C4: ②세부 업무명 | D4: ③단위프로세스명 | E4: 단위프로세스 설명 | F4: ④FP유형 | G4: ⑤가중치
B5: < SLM 스마트 물관리 시스템 > | C5: 1. 실시간 감시
D6: 통합 대시보드 | E6: 시설유형별 KPI·이상 시설·유량 불균형·설비 장애·최근 경보 종합 표출 | F6: EO | G6: =IF(F6="","",IF(F6="EI",4,IF(F6="EO",5.2,IF(F6="EQ",3.9,IF(F6="ILF",7.5,IF(F6="EIF",5.4,"")))))) | H6: Y
D7: 대시보드 집계 데이터 | E7: 이상 스캔·물수지·장애 집계 캐시 (디스크 영속화 포함) | F7: ILF | G7: =IF(F7="","",IF(F7="EI",4,IF(F7="EO",5.2,IF(F7="EQ",3.9,IF(F7="ILF",7.5,IF(F7="EIF",5.4,"")))))) | H7: Y
D8: 시작 페이지 | E8: 로그인 후 첫 화면(랜딩) 구성·바로가기 | F8: EQ | G8: =IF(F8="","",IF(F8="EI",4,IF(F8="EO",5.2,IF(F8="EQ",3.9,IF(F8="ILF",7.5,IF(F8="EIF",5.4,""))))))
D9: GIS 관망도 | E9: 오프라인 지도 위 시설·관로·블록 레이어와 실시간 상태 표출 | F9: EO | G9: =IF(F9="","",IF(F9="EI",4,IF(F9="EO",5.2,IF(F9="EQ",3.9,IF(F9="ILF",7.5,IF(F9="EIF",5.4,"")))))) | H9: Y
D10: GIS 시설 상세 팝업 | E10: 시설 클릭 → 현재값·경보·바로가기 팝업 | F10: EQ | G10: =IF(F10="","",IF(F10="EI",4,IF(F10="EO",5.2,IF(F10="EQ",3.9,IF(F10="ILF",7.5,IF(F10="EIF",5.4,""))))))
D11: GIS 타임라인 스크러버 | E11: 24h 되감기/재생·배속·알람 도트 | F11: EO | G11: =IF(F11="","",IF(F11="EI",4,IF(F11="EO",5.2,IF(F11="EQ",3.9,IF(F11="ILF",7.5,IF(F11="EIF",5.4,""))))))
D12: GIS 시설 좌표 관리 | E12: 시설 좌표 등록·수정 (지도 설정) | F12: EI | G12: =IF(F12="","",IF(F12="EI",4,IF(F12="EO",5.2,IF(F12="EQ",3.9,IF(F12="ILF",7.5,IF(F12="EIF",5.4,""))))))
D13: 실시간 계통도 | E13: SVG 계통도·유량 비례 엣지·흐름 애니메이션·미니맵·검색 | F13: EO | G13: =IF(F13="","",IF(F13="EI",4,IF(F13="EO",5.2,IF(F13="EQ",3.9,IF(F13="ILF",7.5,IF(F13="EIF",5.4,"")))))) | H13: Y
D14: 계통도 노드 상세 | E14: 노드별 Q/H/P 수치 오버레이·트렌드 패널 | F14: EQ | G14: =IF(F14="","",IF(F14="EI",4,IF(F14="EO",5.2,IF(F14="EQ",3.9,IF(F14="ILF",7.5,IF(F14="EIF",5.4,""))))))
D15: 태그 모니터링 | E15: 모니터링 그룹 현재값·이상 카테고리 9종 필터·정렬·우클릭 트렌드 | F15: EO | G15: =IF(F15="","",IF(F15="EI",4,IF(F15="EO",5.2,IF(F15="EQ",3.9,IF(F15="ILF",7.5,IF(F15="EIF",5.4,"")))))) | H15: Y
D16: 시설별 모니터링(배수지) | E16: 배수지 트렌드·HH/LL 가이드·재생·시간 네비게이션 | F16: EO | G16: =IF(F16="","",IF(F16="EI",4,IF(F16="EO",5.2,IF(F16="EQ",3.9,IF(F16="ILF",7.5,IF(F16="EIF",5.4,"")))))) | H16: Y
D17: 시설별 모니터링(가압장) | E17: 가압장 펌프·압력·유량 트렌드 모니터링 | F17: EO | G17: =IF(F17="","",IF(F17="EI",4,IF(F17="EO",5.2,IF(F17="EQ",3.9,IF(F17="ILF",7.5,IF(F17="EIF",5.4,""))))))
D18: 시설별 모니터링(블록) | E18: 블록 유량·압력 트렌드 모니터링 | F18: EO | G18: =IF(F18="","",IF(F18="EI",4,IF(F18="EO",5.2,IF(F18="EQ",3.9,IF(F18="ILF",7.5,IF(F18="EIF",5.4,""))))))
D19: 모니터링 임계 설정 | E19: HH/LL 임계 듀얼모드(상수/태그참조) 설정 | F19: EI | G19: =IF(F19="","",IF(F19="EI",4,IF(F19="EO",5.2,IF(F19="EQ",3.9,IF(F19="ILF",7.5,IF(F19="EIF",5.4,""))))))
D20: 상황실 키오스크 | E20: 기존 화면 iframe 상주 순환·크롬 제거·하단 바(시계·티커) | F20: EO | G20: =IF(F20="","",IF(F20="EI",4,IF(F20="EO",5.2,IF(F20="EQ",3.9,IF(F20="ILF",7.5,IF(F20="EIF",5.4,"")))))) | H20: Y
D21: 키오스크 경보 인터럽트 | E21: 새 경고 감지 시 경보 화면 전환·배너·재인터럽트 방지 | F21: EO | G21: =IF(F21="","",IF(F21="EI",4,IF(F21="EO",5.2,IF(F21="EQ",3.9,IF(F21="ILF",7.5,IF(F21="EIF",5.4,""))))))
D22: 키오스크 설정 | E22: 순환 화면 목록·순서, 야간 밝기, KPI 스트립 설정 | F22: EI | G22: =IF(F22="","",IF(F22="EI",4,IF(F22="EO",5.2,IF(F22="EQ",3.9,IF(F22="ILF",7.5,IF(F22="EIF",5.4,""))))))
C23: 2. 경보 관리
D24: 경보 데이터 | E24: 경보 발생·해제·확인·판정 이력 (하이퍼테이블 연계) | F24: ILF | G24: =IF(F24="","",IF(F24="EI",4,IF(F24="EO",5.2,IF(F24="EQ",3.9,IF(F24="ILF",7.5,IF(F24="EIF",5.4,"")))))) | H24: Y
D25: 진행중 경보 현황 | E25: 진행중 경보 목록·반복 경보 접기(반복 N회)·심각도 구분 | F25: EO | G25: =IF(F25="","",IF(F25="EI",4,IF(F25="EO",5.2,IF(F25="EQ",3.9,IF(F25="ILF",7.5,IF(F25="EIF",5.4,"")))))) | H25: Y
D26: 경보 이력 조회 | E26: 기간·등급·시설 필터 경보 이력 조회 | F26: EQ | G26: =IF(F26="","",IF(F26="EI",4,IF(F26="EO",5.2,IF(F26="EQ",3.9,IF(F26="ILF",7.5,IF(F26="EIF",5.4,""))))))
D27: 반복 경보 순위 | E27: 채터링/만성 판정·순위표·조치 구분 제시 | F27: EO | G27: =IF(F27="","",IF(F27="EI",4,IF(F27="EO",5.2,IF(F27="EQ",3.9,IF(F27="ILF",7.5,IF(F27="EIF",5.4,""))))))
D28: 경보 확인 처리 | E28: 확인/해제 기록·최초 확인자 책임 추적 | F28: EI | G28: =IF(F28="","",IF(F28="EI",4,IF(F28="EO",5.2,IF(F28="EQ",3.9,IF(F28="ILF",7.5,IF(F28="EIF",5.4,""))))))
D29: 미확인 경보 상신 | E29: 경고 N분 미확인 시 전체 채널 1회 멱등 상신 | F29: EO | G29: =IF(F29="","",IF(F29="EI",4,IF(F29="EO",5.2,IF(F29="EQ",3.9,IF(F29="ILF",7.5,IF(F29="EIF",5.4,""))))))
D30: 경보 분석 상세 | E30: 근본원인 분류·위기대응 섹션·연관 비상연락처 매칭 | F30: EO | G30: =IF(F30="","",IF(F30="EI",4,IF(F30="EO",5.2,IF(F30="EQ",3.9,IF(F30="ILF",7.5,IF(F30="EIF",5.4,"")))))) | H30: Y
D31: 근본원인 자동 분류 | E31: 경보 발생 원인 자동 분류 (주기 작업) | F31: EO | G31: =IF(F31="","",IF(F31="EI",4,IF(F31="EO",5.2,IF(F31="EQ",3.9,IF(F31="ILF",7.5,IF(F31="EIF",5.4,""))))))
D32: 오탐 라벨 판정 | E32: 3분법(real/false/check) 1클릭 판정·백필 체계 | F32: EI | G32: =IF(F32="","",IF(F32="EI",4,IF(F32="EO",5.2,IF(F32="EQ",3.9,IF(F32="ILF",7.5,IF(F32="EIF",5.4,""))))))
D33: 오탐 분석 통계 | E33: 주별 오탐률 추이·분류별 현황 | F33: EO | G33: =IF(F33="","",IF(F33="EI",4,IF(F33="EO",5.2,IF(F33="EQ",3.9,IF(F33="ILF",7.5,IF(F33="EIF",5.4,""))))))
D34: 임계 도달 예측 | E34: 수위 LEI↔LEC 페어 선형 외삽·ETA 구간 표시 | F34: EO | G34: =IF(F34="","",IF(F34="EI",4,IF(F34="EO",5.2,IF(F34="EQ",3.9,IF(F34="ILF",7.5,IF(F34="EIF",5.4,""))))))
D35: 알람 캘린더 | E35: 일자별 경보 발생 캘린더 조회 | F35: EQ | G35: =IF(F35="","",IF(F35="EI",4,IF(F35="EO",5.2,IF(F35="EQ",3.9,IF(F35="ILF",7.5,IF(F35="EIF",5.4,""))))))
D36: 알람 팝업(위기대응 모달) | E36: 새 경고 감지 → 모달 강제(주의는 toast)·4액션 | F36: EO | G36: =IF(F36="","",IF(F36="EI",4,IF(F36="EO",5.2,IF(F36="EQ",3.9,IF(F36="ILF",7.5,IF(F36="EIF",5.4,"")))))) | H36: Y
D37: 누수 의심 알림 | E37: 야간최소유량 CUSUM 자동 감지·선정 사유 서술·확인 처리 | F37: EO | G37: =IF(F37="","",IF(F37="EI",4,IF(F37="EO",5.2,IF(F37="EQ",3.9,IF(F37="ILF",7.5,IF(F37="EIF",5.4,"")))))) | H37: Y
D38: 누수 알림 확인 처리 | E38: 누수 의심 건 확인·상태 변경 | F38: EI | G38: =IF(F38="","",IF(F38="EI",4,IF(F38="EO",5.2,IF(F38="EQ",3.9,IF(F38="ILF",7.5,IF(F38="EIF",5.4,""))))))
D39: 작업관리 | E39: 작업 등록·조회·알람 억제 시간 설정 | F39: EI | G39: =IF(F39="","",IF(F39="EI",4,IF(F39="EO",5.2,IF(F39="EQ",3.9,IF(F39="ILF",7.5,IF(F39="EIF",5.4,"")))))) | H39: Y
D40: 작업 이력 데이터 | E40: 작업·조치 이력 (장애 기록과 연계) | F40: ILF | G40: =IF(F40="","",IF(F40="EI",4,IF(F40="EO",5.2,IF(F40="EQ",3.9,IF(F40="ILF",7.5,IF(F40="EIF",5.4,""))))))
D41: 펌프 가동 변경 | E41: 펌프 제어모드·가동 변경 기록 관리 | F41: EI | G41: =IF(F41="","",IF(F41="EI",4,IF(F41="EO",5.2,IF(F41="EQ",3.9,IF(F41="ILF",7.5,IF(F41="EIF",5.4,""))))))
...

Sheet SW개발비 산정
B1: "SLM 스마트 물관리 시스템" 소프트웨어 개발비 산정
I2: (소프트웨어사업 대가산정 가이드, KOSA)
B4: ○ 개발원가 산정 | J4: (단위: 원)
B5: 총기능점수 | C5: 기능점수당 단가 | D5: 보정계수 | I5: 개발원가
D6: 규모 | E6: 연계복잡성 | F6: 성능 | G6: 운영환경 | H6: 보안성
B7: ='FP산정(간이법)'!G159 | C7: 605784 | D7: =J21 | E7: =J22 | F7: =J23 | G7: =J24 | H7: =J25 | I7: =ROUND(PRODUCT(B7:H7),0)
B8: 합계(보정 후 개발원가) | I8: =I7
B9: 이윤 (개발원가의 25% 이내) | H9: 0.2 | I9: =ROUND(I8*H9,0)
B10: 직접경비 | I10: =I17
B11: 소프트웨어 개발비 (부가세 별도) | I11: =SUM(I8:I10)
B13: ○ 직접경비
B14: 구분 | C14: 산출내역 | I14: 금액
C15: 직접경비 요소 없음 (폐쇄망 온프레미스 — 발주자 제공 인프라 기준) | I15: 0
B17: 합 계 | I17: =SUM(I15:I16)
B19: ○ 보정계수 산정
B20: 보정계수 구분 | C20: 복잡도 및 난이도 수준 | J20: 보정계수
B21: SW규모 | C21: =0.4057 × (ln(FP) − 7.1978)² + 0.8878 (500FP 미만 1.28, 3,000FP 초과 1.153) | J21: =IF(B7<500,1.28,IF(B7>3000,1.153,ROUND(0.4057*(LN(B7)-7.1978)^2+0.8878,4)))
B22: 연계복잡성 | C22: 1. 타 기관 연계 없음 (폐쇄망 단독 운영 — SCADA 연계는 내부 연계) | J22: 0.88
B23: 성능 요구수준 | C23: 3. 응답시간·처리율이 피크타임에 중요하며 처리 시한이 명시 (실시간 감시·알람) | J23: 1
B24: 운영환경 호환성 | C24: 3. 호환성 요구 있음 — 유사 HW·SW 환경(고객별 온프레미스 설치) | J24: 1.06
B25: 보안성 요구수준 | C25: 2. 2가지 요구사항 포함 (암호화(JWT·bcrypt)·시큐어코딩) | J25: 1
B27: ○ FP 집계
B28: 구분 | C28: ILF | D28: EIF | E28: EI | F28: EO | G28: EQ | H28: 계
B29: 복잡도(가중치) | C29: 7.5 | D29: 5.4 | E29: 4 | F29: 5.2 | G29: 3.9
B30: 기능수 | C30: =COUNTIF('FP산정(간이법)'!$F$5:$F$158,"ILF") | D30: =COUNTIF('FP산정(간이법)'!$F$5:$F$158,"EIF") | E30: =COUNTIF('FP산정(간이법)'!$F$5:$F$158,"EI") | F30: =COUNTIF('FP산정(간이법)'!$F$5:$F$158,"EO") | G30: =COUNTIF('FP산정(간이법)'!$F$5:$F$158,"EQ") | H30: =SUM(C30:G30)
B31: 기능점수 | C31: =SUMIF('FP산정(간이법)'!$F$5:$F$158,"ILF",'FP산정(간이법)'!$G$5:$G$158) | D31: =SUMIF('FP산정(간이법)'!$F$5:$F$158,"EIF",'FP산정(간이법)'!$G$5:$G$158) | E31: =SUMIF('FP산정(간이법)'!$F$5:$F$158,"EI",'FP산정(간이법)'!$G$5:$G$158) | F31: =SUMIF('FP산정(간이법)'!$F$5:$F$158,"EO",'FP산정(간이법)'!$G$5:$G$158) | G31: =SUMIF('FP산정(간이법)'!$F$5:$F$158,"EQ",'FP산정(간이법)'!$G$5:$G$158) | H31: =SUM(C31:G31)

Sheet (참조)보정계수
B1: 보정계수 참조표 — FP방식(간이법)
B3: ○ 규모 보정계수
B4: SW규모 | C4: =0.4057 × (ln(기능점수) − 7.1978)² + 0.8878 (단, 500FP 미만 1.28 / 3,000FP 초과 1.153)
B6: ○ 애플리케이션 복잡도 보정계수
B7: 연계복잡성 | C7: 1. 타 기관 연계 없음 | H7: 0.88
C8: 2. 1~2개의 타 기관 연계 | H8: 0.94
C9: 3. 3~5개의 타 기관 연계 | H9: 1
C10: 4. 6~10개의 타 기관 연계 | H10: 1.06
C11: 5. 10개 초과의 타 기관 연계 | H11: 1.12
B12: 성능 요구수준 | C12: 1. 응답성능에 대한 특별한 요구사항이 없다. | H12: 0.91
C13: 2. 요구사항이 있으나 특별한 조치는 불필요 | H13: 0.95
C14: 3. 응답시간·처리율이 피크타임에 중요, 처리 시한 명시 | H14: 1
C15: 4. 모든 업무시간에 중요, 처리 시한 명시 | H15: 1.05
C16: 5. 엄격 — 설계·구현 단계 성능 분석도구 필요 | H16: 1.09
B17: 운영환경 호환성 | C17: 1. 요구사항 없음 | H17: 0.94
C18: 2. 동일 HW·SW 환경 | H18: 1
C19: 3. 유사 HW·SW 환경 | H19: 1.06
C20: 4. 이질적 HW·SW 환경 | H20: 1.13
C21: 5. 4 + 운영 절차 문서화·사전 모의훈련 요구 | H21: 1.19
B22: 보안성 수준 | C22: 1. 1가지 보안 요구사항 | H22: 0.97
C23: 2. 2가지 | H23: 1
C24: 3. 3가지 | H24: 1.03
C25: 4. 4가지 | H25: 1.06
C26: 5. 5가지 이상 | H26: 1.08

Sheet 직접경비
A1: 직접경비 항목 (참조)
A2: 항목 | B2: 설명
A3: 컴퓨터시스템 사용료 | B3: 발주자가 제공하지 않아 자체/제3자 조달 시
A4: 소프트웨어 도구 사용료 | B4: 발주자 요구에 의한 SW 패키지 사용료
A5: 지급이자 | B5: 선투자 후정산 사업의 경우
A6: 특정기술 전문가 비용 | B6: 발주자 요구의 특정기술 도입 관련
A7: 여비 | B7: 운임·현지교통비·숙박비 등
A8: 특수자료비 | B8: 특허·노하우 사용료
A9: 인쇄·청사진비 | B9: 산출물·보고서 인쇄·복사비
A10: 자료조사비 | B10: 문헌·전문도서 구입
A11: 기자재시험비 | B11: 기자재 시험 소요 비용
A12: 위탁비(외주비) | B12: 일부 외부 위탁 비용
A13: 현장운영비 | B13: 보조요원 급여·현장사무실 임차·운영비
... A15: 기타 | B15: 그 밖에 특별히 소요되는 직접비용

Sheet 엔지니어링 내역
A1: ■ SLM 구축·설치 엔지니어링 내역 (설계금액)
A2: 구분 | B2: 항목 | C2: 작업 내용 | D2: M/M | G2: 금액(원) | J2: 기간 | K2: 비고
D3: IT지원 | E3: 응용SW개발 | F3: 정보시스템운용 | G3: IT지원 | H3: 응용SW개발 | I3: 정보시스템운용
A4: 설치 | B4: 서버 스택 설치·구성 | C4: Docker 스택(DB·백엔드·프런트·Node-RED)·프로덕션 빌드·TLS 구성 | E4: =0.048*2 | F4: =0.048*5 | H4: =E4*($B$41*20.5) | I4: =F4*($B$42*20.5) | J4: 1주
B5: DB 구축 | C5: 스키마·마이그레이션 적용·기초 시드·압축 정책 | E5: =0.048*2 | F5: =0.048*3 | H5: =E5*($B$41*20.5) | I5: =F5*($B$42*20.5) | J5: 1주
B6: AI 모델 설치 | C6: Ollama 모델(비전·임베딩) 오프라인 설치·검증 | F6: =0.048*2 | I6: =F6*($B$42*20.5) | J6: 2일 | K6: 폐쇄망 반입
B7: 모델 웨이트 번들 반입 | C7: Chronos·Whisper 번들 설치·sha256 검증 | F7: =0.048*2 | I7: =F7*($B$42*20.5) | J7: 2일
B8: GIS 지도 번들 구축 | C8: 관할 영역 pmtiles 추출·글리프 반입·검증 | E8: =0.048*3 | H8: =E8*($B$41*20.5) | J8: 3일 | K8: 관할별 재추출
A9: 데이터 구축 | B9: 태그 마스터 구축 | C9: 태그 등록·DATAINFO 변환룰 적용·검수 (약 2,700태그) | D9: =0.048*10 | E9: =0.048*10 | G9: =D9*($B$40*20.5) | H9: =E9*($B$41*20.5) | J9: 2주 | K9: 룰 재현율 채점
B10: 시설 기초정보 구축 | C10: 배수지·가압장·감압·블록 기초정보 (약 120개소) | D10: =0.048*10 | G10: =D10*($B$40*20.5) | J10: 2주
B11: 계통도 구축 | C11: 수계 관계(flow-map)·캔버스 배치·정합 lint 0건 | E11: =0.048*5 | H11: =E11*($B$41*20.5) | J11: 1주
B12: GIS 좌표 구축 | C12: 시설 좌표 등록·현장 검증 | D12: =0.048*5 | G12: =D12*($B$40*20.5) | J12: 1주
B13: 통신망 구축 | C13: 장비·링크 등록 (약 300대)·토폴로지 검증 | D13: =0.048*7 | G13: =D13*($B$40*20.5) | J13: 1.5주
B14: EPANET 모델 구축 | C14: INP 모델 작성·실측 유량 매핑·시뮬 검증 | E14: =0.048*10 | H14: =E14*($B$41*20.5) | J14: 2주 | K14: B1 SKU 시
A15: 연계 | B15: SCADA 수집 연계 | C15: Node-RED 수집 플로우 구성·태그 매핑 | E15: =0.048*10 | F15: =0.048*5 | H15: =E15*($B$41*20.5) | I15: =F15*($B$42*20.5) | J15: 2주
B16: 알람 조건 엔진 구성 | C16: 수위/압력/펌프 조건검토 플로우 현장 임계 보정 | E16: =0.048*10 | H16: =E16*($B$41*20.5) | J16: 2주
A17: 시험·인수 | B17: 구축 완결성 검수 | C17: 검수 6종 warn 0 달성·품질 게이트 통과 | E17: =0.048*5 | H17: =E17*($B$41*20.5) | J17: 1주 | K17: 인수 기준
B18: 통합 시험 | C18: 채팅 스모크·알람 시나리오·통화(LTE) 시험 | E18: =0.048*5 | H18: =E18*($B$41*20.5) | J18: 1주
B19: 교육·인수인계 | C19: 운영자 교육·운영 문서 인수 | D19: =0.048*5 | G19: =D19*($B$40*20.5) | J19: 1주
B20: 합계 | D20: =SUM(D4:D19) | E20: =SUM(E4:E19) | F20: =SUM(F4:F19) | G20: =SUM(G4:G19) | H20: =SUM(H4:H19) | I20: =SUM(I4:I19)
A22: 직접인건비 | C22: 설치·데이터 구축·연계·시험 엔지니어링 합계 | H22: =G20+H20+I20
A23: 제경비 | C23: 직접인건비의 110~120% (상한 120% 적용) | H23: =ROUND(H22*1.2,0)
A24: 기술료 | C24: (직접인건비+제경비)의 20~40% (하한 20% 적용) | H24: =ROUND((H22+H23)*0.2,0)
A25: 엔지니어링 총계 (부가세 별도) | H25: =H22+H23+H24
A39: SW기술자 평균임금 공표 (2025) | C39: 월 20.5일 기준 · 1일 = 0.048 M/M
A40: IT지원기술자 | B40: 245535
A41: 응용SW개발자 | B41: 337061
A42: 정보시스템운용자 | B42: 492943
